<?xml version="1.0"?>
<mujoco model="KUKAiiwa14">

  <option>
    <!-- <flag energy="enable" contact="disable"/> -->
  </option>


  <visual>
    <global offwidth="1080" offheight="720"/>
    <headlight diffuse="0.6 0.6 0.6" ambient="0.3 0.3 0.3" specular="0 0 0"/>
  </visual>
  <compiler convexhull="false" angle="radian" meshdir="../meshes/kuka/"/>
  <statistic meansize="0.217635" extent="1.52079" center="-0.0055099 0.00418408 0.623461"/>
  <asset>
    <mesh name="iiwa_base" file="iiwa_base.stl"/>
    <mesh name="iiwa_link_1" file="iiwa_link_1.stl"/>
    <mesh name="iiwa_link_2" file="iiwa_link_2.stl"/>
    <mesh name="iiwa_link_3" file="iiwa_link_3.stl"/>
    <mesh name="iiwa_link_4" file="iiwa_link_4.stl"/>
    <mesh name="iiwa_link_5" file="iiwa_link_5.stl"/>
    <mesh name="iiwa_link_6" file="iiwa_link_6.stl"/>
    <mesh name="iiwa_link_7" file="iiwa_link_7.stl"/>
    <mesh name="kuka_to_sensor_mount" file="kuka_to_sensor_mount.stl" scale="0.001 0.001 0.001"/>
    <mesh name="sensor_to_case_mount" file="sensor_to_case_mount.stl" scale="0.001 0.001 0.001"/>
    <mesh name="5674K57_flange_mount_ball_transfer" file="5674K57_flange_mount_ball_transfer.stl" scale="0.0254 0.0254 0.0254"/>
    <texture type="skybox" builtin="gradient" rgb1="0.3 0.5 0.7" rgb2="0 0 0" width="512" height="3072"/>
    <texture type="2d" name="wood" file="../meshes/wood1.png"/>
    <material name="wood" texuniform="true" texture="wood" reflectance="0.0"/>
    <texture name="marker" file="/home/quim/Downloads/4x4_1000-0.png" type="2d"/>
    <texture name="chess" file="/home/quim/Downloads/A4_chessboard.png" type="2d"/>
    <material name="marker-mat" texture="marker"/>
    <material name="chess-mat" texture="chess"/>
  </asset>
  <worldbody>
    <camera name="camera-front" pos="1.1 0.0 .8" euler="0 .5 1.570796"/>

    <body name="L0">
      <geom type="mesh" rgba="0.4 0.4 0.4 1" mesh="iiwa_base" contype="0" conaffinity="0" />
    <body name="L1" pos="0 0 0.1575">
      <inertial pos="0 0 0" quat="0.999999 -0.00117646 0 0" mass="3.94781" diaginertia="0.00455 0.00454002 0.000289976"/>
      <joint name="A1" pos="0 0 0" axis="0 0 1" limited="true" range="-2.96706 2.96706"/>
        <!-- <joint name="A1" pos="0 0 0" axis="0 0 1" /> -->
        <geom type="mesh" rgba="1 0.423529 0.0392157 1" mesh="iiwa_link_1" contype="0" conaffinity="0" />
      <body name="L2" pos="0 0 0.2025" quat="-0.5 0.5 0.5 0.5">
        <inertial pos="0.0003 0.059 0.042" quat="0.5 0.5 -0.5 0.5" mass="4.50275" diaginertia="0.00042 0.00032 0.0001"/>
        <joint name="A2" pos="0 0 0" axis="0 0 1" limited="true" range="-2.0944 2.0944"/>
          <geom type="mesh" rgba="1 0.423529 0.0392157 1" mesh="iiwa_link_2"  contype="0" conaffinity="0"  />
        <body name="L3" pos="0.2045 0 0" quat="0.5 0.5 0.5 0.5">
          <inertial pos="0 0.03 0.13" quat="0.957239 0.0304965 -0.0159101 -0.287245" mass="2.4552" diaginertia="0.00226409 0.00216273 0.000723178"/>
          <joint name="A3" pos="0 0 0" axis="0 0 1" limited="true" range="-2.96706 2.96706"/>
            <geom type="mesh" rgba="1 0.423529 0.0392157 1" mesh="iiwa_link_3"  contype="0" conaffinity="0" />
          <body name="L4" pos="0 0 0.2155" quat="0.707107 0.707107 0 0">
            <inertial pos="0 0.067 0.034" quat="0.458936 0.488707 -0.524616 0.52471" mass="2.61155" diaginertia="0.0497286 0.0383502 0.0113812"/>
            <joint name="A4" pos="0 0 0" axis="0 0 1" limited="true" range="-2.0944 2.0944"/>
            <geom type="mesh" rgba="1 0.423529 0.0392157 1" mesh="iiwa_link_4"  contype="0" conaffinity="0"  />
            <body name="L5" pos="0 0.1845 0" quat="0.707107 -0.707107 0 0">
              <inertial pos="0.0001 0.021 0.076" quat="0.656211 -0.00141917 -0.00124336 0.754575" mass="3.41" diaginertia="0.0028414 0.00276864 0.000119962"/>
              <joint name="A5" pos="0 0 0" axis="0 0 1" limited="true" range="-2.96706 2.96706"/>
              <geom type="mesh" rgba="1 0.423529 0.0392157 1" mesh="iiwa_link_5" contype="0" conaffinity="0"  />
              <body name="L6" pos="0 -0.0607 0.2155" quat="-0.5 0.5 0.5 0.5">
                <inertial pos="0 0.0006 0.0004" quat="0.518527 0.469977 0.52024 0.489491" mass="3.38795" diaginertia="0.00281422 0.00231739 0.000498395"/>
                <joint name="A6" pos="0 0 0" axis="0 0 1" limited="true" range="-2.0944 2.0944"/>
                <geom type="mesh" rgba="1 0.423529 0.0392157 1" mesh="iiwa_link_6" contype="0" conaffinity="0"  />
                <body name="L7" pos="0.081 0 0.0607" quat="0.5 0.5 0.5 0.5">
                  <inertial pos="0 0 0.02" quat="0.734569 0.00610365 0.032436 0.677731" mass="0.35432" diaginertia="0.010859 0.00794746 0.00291357"/>
                  <joint name="A7" pos="0 0 0" axis="0 0 1" limited="true" range="-3.05433 3.05433"/>
                  <geom type="mesh" rgba="0.4 0.4 0.4 1" mesh="iiwa_link_7" contype="0" conaffinity="0"  />
                  <body name="pusher">
                    <inertial pos="0 0 0.145" mass=".1"/>
                    <geom name="pusher_stick" size="0.02 0.05" pos="0 0 0.095" type="cylinder" rgba="0 0.8 0 0.5"  />
                    <geom name="pusher_tip" size="0.01" pos="0 0 0.145" rgba="0.8 0 0 1" contype="0" conaffinity="0"    />
                    <geom type="cylinder" size="0.02 0.2" rgba="1 0 0 1" pos="0.2 0 0.145" euler="0 1.571 0" contype="0" conaffinity="0" />
                    <geom type="cylinder" size="0.02 0.2" rgba="0 1 0 1" pos="0 0.2 0.145" euler="-1.571 0 0" contype="0" conaffinity="0"/>
                    <geom type="cylinder" size="0.02 0.2" rgba="0 0 1 1" pos="0 .0 0.345" contype="0" conaffinity="0" />
                  </body>
                </body>
              </body>
            </body>
          </body>
        </body>
      </body>
    </body>
      </body>




    <body name="camera-font-axes" pos="1.1 0.0 .8" euler="0 .5  1.570796">
      <geom type="cylinder" size="0.02 0.2" rgba="1 0 0 1" pos="0.2 0 0" euler="0 1.571 0"/>
      <!-- X-axis -->
      <geom type="cylinder" size="0.02 0.2" rgba="0 1 0 1" pos="0 0.2 0" euler="-1.571 0 0"/>
      <!-- Y-axis -->
      <geom type="cylinder" size="0.02 0.2" rgba="0 0 1 1" pos="0 0 0.2"/>
      <!-- Z-axis -->
    </body>
    <camera name="camera-right" pos="0.159 1.554 1.412" xyaxes="-0.975 -0.222 -0.000 0.146 -0.642 0.753"/>
    <body name="camera-right-axes" pos="0.159 1.554 1.412" xyaxes="-0.975 -0.222 -0.000 0.146 -0.642 0.753">
      <geom type="cylinder" size="0.02 0.2" rgba="1 0 0 1" pos="0.2 0 0" euler="0 1.571 0"/>
      <!-- X-axis -->
      <geom type="cylinder" size="0.02 0.2" rgba="0 1 0 1" pos="0 0.2 0" euler="-1.571 0 0"/>
      <!-- Y-axis -->
      <geom type="cylinder" size="0.02 0.2" rgba="0 0 1 1" pos="0 0 0.2"/>
      <!-- Z-axis -->
    </body>
    <camera name="camera-left" pos="0.246 -0.930 1.486" xyaxes="0.962 -0.271 -0.000 0.235 0.832 0.502"/>
    <body name="camera-left-axes" pos="0.246 -0.930 1.486" xyaxes="0.962 -0.271 -0.000 0.235 0.832 0.502">
      <geom type="cylinder" size="0.02 0.2" rgba="1 0 0 1" pos="0.2 0 0" euler="0 1.571 0"/>
      <!-- X-axis -->
      <geom type="cylinder" size="0.02 0.2" rgba="0 1 0 1" pos="0 0.2 0" euler="-1.571 0 0"/>
      <!-- Y-axis -->
      <geom type="cylinder" size="0.02 0.2" rgba="0 0 1 1" pos="0 0 0.2"/>
      <!-- Z-axis -->
    </body>
    <!---->
    <light pos="1 0 1.5" dir="0 0 -1" directional="true"/>
    <light pos="-1 0 1.5" dir="0 0 -1" directional="true"/>
    <body name="floorb">
      <geom name="floor" size="1.40 .4 .1" type="plane" material="wood" friction=".1 0.005 0.001"  priority="2" condim="4"/>
    </body>
    <geom type="mesh" rgba="0.4 0.4 0.4 1" mesh="iiwa_base" contype="0" conaffinity="5"/>
    <body name="cube" pos="-0.4 0.2 0.05">
      <freejoint name="cube_j"/>
      <geom type="box" mass="0.1" pos="0 0 0" rgba="1 1 1 1" size="0.15 0.15 0.05"/>
      <geom name="geo-marker" pos="0 0 0.05" size="0.1 0.1 0.0005" type="box" material="marker-mat"/>
    </body>

    <body name="cube_small" pos="0.5 0.0 0.05">
      <freejoint name="cube_small_j"/>
      <geom type="box" mass="0.01" pos="0 0 0" rgba="1 1 1 1" size="0.05 0.05 0.05"/>
      <!-- <geom name="geo-marker" pos="0 0 0.05" size="0.1 0.1 0.0005" type="box" material="marker-mat"/> -->
    </body>



    <body name="chessboard" pos=".0 0 0">
      <freejoint name="chessboard_joint"/>
      <geom name="geo-chess" pos="0 0 0.0" size=".105 0.1485 0.0005" type="box" material="chess-mat" contype="0" conaffinity="0" />
      <geom type="sphere" size=".01" rgba="1 0 0 0" contype="0" conaffinity="0"/>
    </body>
    <body name="big_marker" pos=".5 .1 0">
      <freejoint name="big_marker_j"/>
      <geom pos="0 0 0.0" size="0.2 0.2 0.0005" type="box" material="marker-mat" contype="0" conaffinity="0" />
      <geom name="big_marker_p1" pos=".2 .2 0" size="0.002" type="sphere" rgba="1 0 0 1" contype="0" conaffinity="0"
        />
      <geom name="big_marker_p2" pos=".2 -.2 0" size="0.002" type="sphere" rgba="1 0 0 1" contype="0" conaffinity="0"
        />
      <geom name="big_marker_p3" pos="-.2 -.2 0" size="0.002" type="sphere" rgba="1 0 0 1" contype="0" conaffinity="0"
        />
      <geom name="big_marker_p4" pos="-.2 .2 0" size="0.002" type="sphere" rgba="1 0 0 1" contype="0" conaffinity="0" />
    </body>
    <body name="pusher_tip_goalb" pos=".6 .2 .05" euler="-3.14159 0 3.14159" >
    <!-- <body name="pusher_tip_goalb" pos=".4 .0 .3" euler="-3.14159 0 0" > -->
      <geom name="pusher_tip_goal" type="sphere" size="0.02" rgba="1. 0. 0. .5" contype="0" conaffinity="0"  />
      <geom type="cylinder" size="0.02 0.2" rgba="1 0 0 1" pos="0.2 0. 0." euler="0 1.571 0" contype="0" conaffinity="0" />
      <geom type="cylinder" size="0.02 0.2" rgba="0 1 0 1" pos="0 0.2 0." euler="-1.571 0 0" contype="0" conaffinity="0" />
      <geom type="cylinder" size="0.02 0.2" rgba="0 0 1 1" pos="0 .0  .2" contype="0" conaffinity="0" />
    </body>
    <!-- <body name='marker1' pos='.5 0 0'> -->
    <!--   <geom pos='0 0 0.0' size=".02" type="sphere" rgba="1 0 0 1"/> -->
    <!-- </body> -->
    <!-- Robot -->
    <body name="cage" pos="0.55 0.0 0.0">
      <geom name="cage-g1" size="0.4 0.02 .015" pos=".0 -0.4 0.015" type="box" rgba="0.6 0.6 0.6 1"/>
      <geom name="cage-g2" size=".4 .02 .015" type="box" pos="+.0 0.4 0.015" rgba="0.6 0.6 0.6 1"/>
      <geom name="cage-g3" size="0.02 0.36 .015" pos="-.2 -0.0 0.015" type="box" rgba="0.6 0.6 0.6 1"/>
      <geom name="cage-g4" size=".02 .36 .015" type="box" pos="+.2 +.0 0.015" rgba="0.6 0.6 0.6 1"/>
    </body>


    <body name="limit-ws"> 
      <geom name="x+y+" size="0.02" pos=".72 0.3 0.2"  rgba="0.6 0.6 0.6 1" contype="0" conaffinity="0" />
      <geom name="x+y-" size="0.02" pos=".72 -.3 0.2"  rgba="0.6 0.6 0.6 1" contype="0" conaffinity="0" />
      <geom name="x-y-" size="0.02" pos=".35 -0.3 0.2"  rgba="0.6 0.6 0.6 1" contype="0" conaffinity="0" />
      <geom name="x-y+" size="0.02" pos=".35 0.3 0.2"  rgba="0.6 0.6 0.6 1" contype="0" conaffinity="0" />
    </body>





  </worldbody>



  <actuator>
    <!-- <motor name="A1" joint="A1" /> -->
    <!-- <motor name="A2" joint="A2" /> -->
    <!-- <motor name="A3" joint="A3" /> -->
    <!-- <motor name="A4" joint="A4" /> -->
    <!-- <motor name="A5" joint="A5" /> -->
    <!-- <motor name="A6" joint="A6" /> -->
    <!-- <motor name="A7" joint="A7" /> -->

    <motor name="A1" joint="A1" />
    <motor name="A2" joint="A2" />
    <motor name="A3" joint="A3" />
    <motor name="A4" joint="A4" />
    <motor name="A5" joint="A5" />
    <motor name="A6" joint="A6" />
    <motor name="A7" joint="A7" />
  </actuator>
</mujoco>
